<?xml version="1.0"?>
<!-- =================================================================================== -->
<!-- |    EDITING THIS FILE BY HAND IS NOT RECOMMENDED                                 | -->
<!-- =================================================================================== -->
<!-- \n  Copyright (c) 2022 PAL Robotics S.L. All rights reserved.\n\n  Licensed under the Apache License, Version 2.0 (the "License");\n  you may not use this file except in compliance with the License.\n  You may obtain a copy of the License at\n\n      http://www.apache.org/licenses/LICENSE-2.0\n\n  Unless required by applicable law or agreed to in writing, software\n  distributed under the License is distributed on an "AS IS" BASIS,\n  WITHOUT WARRANTIES OR CONDITIONS OF ANY KIND, either express or implied.\n  See the License for the specific language governing permissions and\n  limitations under the License.\n -->
<robot name="tiago">
	<material name="Hey5DarkGrey">
		<color rgba="0.1 0.1 0.1 1.0"/>
	</material>
	<gazebo>
		<plugin filename="libgazebo_ros2_control.so" name="gazebo_ros2_control">
			<!-- in the future move this param file somewhere else -->
			<!-- <parameters>$(find tiago_controller_configuration)/config/gazebo_controller_manager_cfg.yaml</parameters> -->
			<parameters>/opt/ros/humble/share/tiago_controller_configuration/config/gazebo_controller_manager_cfg.yaml</parameters>
			<!-- Do something about multirobot -->
		</plugin>
		<plugin filename="libgazebo_ros_p3d.so" name="gazebo_ros_p3d">
			<body_name>base_footprint</body_name>
			<always_on>true</always_on>
			<update_rate>100.0</update_rate>
			<ros>
				<remapping>odom:=ground_truth_odom</remapping>
			</ros>
		</plugin>
	</gazebo>
	<gazebo>
		<!--- backwards compatibility, used to be gazebo_world_odometry pal plugin-->
		<plugin filename="libgazebo_ros_p3d.so" name="gazebo_ros_odometry">
			<body_name>base_footprint</body_name>
			<always_on>true</always_on>
			<update_rate>1000.0</update_rate>
			<ros>
				<remapping>odom:=floating_base_pose_simulated</remapping>
			</ros>
		</plugin>
	</gazebo>
	<gazebo reference="base_imu_link">
		<sensor name="imu_sensor" type="imu">
			<always_on>1</always_on>
			<update_rate>10.0</update_rate>
			<imu>
				<noise>
					<type>gaussian</type>
					<rate>
						<mean>0.0</mean>
						<stddev>2e-4</stddev>
						<bias_mean>0.0000075</bias_mean>
						<bias_stddev>0.0000008</bias_stddev>
					</rate>
					<accel>
						<mean>0.0</mean>
						<stddev>1.7e-2</stddev>
						<bias_mean>0.1</bias_mean>
						<bias_stddev>0.001</bias_stddev>
					</accel>
				</noise>
			</imu>
			<plugin filename="libgazebo_ros_imu_sensor.so" name="base_imu">
				<ros>
					<!-- publish to /imu/data -->
					<remapping>~/out:=base_imu</remapping>
				</ros>
			</plugin>
		</sensor>
	</gazebo>
	<ros2_control name="ros2_control_tiago_system" type="system">
		<hardware>
			<plugin>mock_components/GenericSystem</plugin>
			<param name="calculate_dynamics">true</param>
		</hardware>
		<joint name="wheel_right_joint">
			<command_interface name="velocity">
				<param name="min">-1</param>
				<param name="max">1</param>
			</command_interface>
			<state_interface name="position"/>
		</joint>
		<transmission name="wheel_right_trans">
			<plugin>transmission_interface/SimpleTransmission</plugin>
			<actuator name="wheel_right_actuator" role="actuator1"/>
			<joint name="wheel_right_joint" role="joint1">
				<mechanical_reduction>1.0</mechanical_reduction>
			</joint>
		</transmission>
		<joint name="wheel_left_joint">
			<command_interface name="velocity">
				<param name="min">-1</param>
				<param name="max">1</param>
			</command_interface>
			<state_interface name="position"/>
		</joint>
		<transmission name="wheel_left_trans">
			<plugin>transmission_interface/SimpleTransmission</plugin>
			<actuator name="wheel_left_actuator" role="actuator1"/>
			<joint name="wheel_left_joint" role="joint1">
				<mechanical_reduction>1.0</mechanical_reduction>
			</joint>
		</transmission>
		<sensor name="base_imu_sensor">
			<state_interface name="orientation.x"/>
			<state_interface name="orientation.y"/>
			<state_interface name="orientation.z"/>
			<state_interface name="orientation.w"/>
			<state_interface name="angular_velocity.x"/>
			<state_interface name="angular_velocity.y"/>
			<state_interface name="angular_velocity.z"/>
			<state_interface name="linear_acceleration.x"/>
			<state_interface name="linear_acceleration.y"/>
			<state_interface name="linear_acceleration.z"/>
		</sensor>
		<joint name="torso_lift_joint">
			<command_interface name="position"/>
			<state_interface name="position"/>
			<state_interface name="velocity"/>
			<state_interface name="effort"/>
		</joint>
		<transmission name="torso_lift_trans">
			<plugin>transmission_interface/SimpleTransmission</plugin>
			<actuator name="torso_lift_actuator" role="actuator1"/>
			<joint name="torso_lift_joint" role="joint1">
				<mechanical_reduction>1.0</mechanical_reduction>
				<offset>0.0</offset>
			</joint>
		</transmission>
		<joint name="head_1_joint">
			<command_interface name="position"/>
			<state_interface name="position"/>
			<state_interface name="velocity"/>
			<state_interface name="effort"/>
		</joint>
		<transmission name="head_1_trans">
			<plugin>transmission_interface/SimpleTransmission</plugin>
			<actuator name="head_1_actuator" role="actuator1"/>
			<joint name="head_1_joint" role="joint1">
				<mechanical_reduction>1.0</mechanical_reduction>
				<offset>0.0</offset>
			</joint>
		</transmission>
		<joint name="head_2_joint">
			<command_interface name="position"/>
			<state_interface name="position"/>
			<state_interface name="velocity"/>
			<state_interface name="effort"/>
		</joint>
		<transmission name="head_2_trans">
			<plugin>transmission_interface/SimpleTransmission</plugin>
			<actuator name="head_2_actuator" role="actuator1"/>
			<joint name="head_2_joint" role="joint1">
				<mechanical_reduction>1.0</mechanical_reduction>
				<offset>0.0</offset>
			</joint>
		</transmission>
		<joint name="arm_1_joint">
			<command_interface name="position"/>
			<command_interface name="velocity"/>
			<command_interface name="effort"/>
			<state_interface name="position"/>
			<state_interface name="velocity"/>
			<state_interface name="effort"/>
		</joint>
		<transmission name="arm_1_trans">
			<plugin>transmission_interface/SimpleTransmission</plugin>
			<actuator name="arm_1_actuator" role="actuator1"/>
			<joint name="arm_1_joint" role="joint1">
				<mechanical_reduction>1.0</mechanical_reduction>
				<offset>0.0</offset>
			</joint>
		</transmission>
		<joint name="arm_2_joint">
			<command_interface name="position"/>
			<command_interface name="velocity"/>
			<command_interface name="effort"/>
			<state_interface name="position"/>
			<state_interface name="velocity"/>
			<state_interface name="effort"/>
		</joint>
		<transmission name="arm_2_trans">
			<plugin>transmission_interface/SimpleTransmission</plugin>
			<actuator name="arm_2_actuator" role="actuator1"/>
			<joint name="arm_2_joint" role="joint1">
				<mechanical_reduction>1.0</mechanical_reduction>
				<offset>0.0</offset>
			</joint>
		</transmission>
		<joint name="arm_3_joint">
			<command_interface name="position"/>
			<command_interface name="velocity"/>
			<command_interface name="effort"/>
			<state_interface name="position"/>
			<state_interface name="velocity"/>
			<state_interface name="effort"/>
		</joint>
		<transmission name="arm_3_trans">
			<plugin>transmission_interface/SimpleTransmission</plugin>
			<actuator name="arm_3_actuator" role="actuator1"/>
			<joint name="arm_3_joint" role="joint1">
				<mechanical_reduction>1.0</mechanical_reduction>
				<offset>0.0</offset>
			</joint>
		</transmission>
		<joint name="arm_4_joint">
			<command_interface name="position"/>
			<command_interface name="velocity"/>
			<command_interface name="effort"/>
			<state_interface name="position"/>
			<state_interface name="velocity"/>
			<state_interface name="effort"/>
		</joint>
		<transmission name="arm_4_trans">
			<plugin>transmission_interface/SimpleTransmission</plugin>
			<actuator name="arm_4_actuator" role="actuator1"/>
			<joint name="arm_4_joint" role="joint1">
				<mechanical_reduction>1.0</mechanical_reduction>
				<offset>0.0</offset>
			</joint>
		</transmission>
		<joint name="arm_5_joint">
			<command_interface name="position"/>
			<command_interface name="velocity"/>
			<command_interface name="effort"/>
			<state_interface name="position"/>
			<state_interface name="velocity"/>
			<state_interface name="effort"/>
		</joint>
		<transmission name="arm_5_trans">
			<plugin>transmission_interface/SimpleTransmission</plugin>
			<actuator name="arm_5_actuator" role="actuator1"/>
			<joint name="arm_5_joint" role="joint1">
				<mechanical_reduction>1.0</mechanical_reduction>
				<offset>0.0</offset>
			</joint>
		</transmission>
		<joint name="arm_6_joint">
			<command_interface name="position"/>
			<command_interface name="velocity"/>
			<command_interface name="effort"/>
			<state_interface name="position"/>
			<state_interface name="velocity"/>
			<state_interface name="effort"/>
		</joint>
		<joint name="arm_7_joint">
			<command_interface name="position"/>
			<command_interface name="velocity"/>
			<command_interface name="effort"/>
			<state_interface name="position"/>
			<state_interface name="velocity"/>
			<state_interface name="effort"/>
		</joint>
		<transmission name="arm_6_arm_7_wrist_trans">
			<plugin>transmission_interface/DifferentialTransmission</plugin>
			<actuator name="arm_6_actuator" role="actuator1">
				<mechanical_reduction>-1.0</mechanical_reduction>
			</actuator>
			<actuator name="arm_7_actuator" role="actuator2">
				<mechanical_reduction>1.0</mechanical_reduction>
			</actuator>
			<joint name="arm_6_joint" role="joint1">
				<mechanical_reduction>1.0</mechanical_reduction>
				<offset>0.0</offset>
			</joint>
			<joint name="arm_7_joint" role="joint2">
				<mechanical_reduction>1.0</mechanical_reduction>
				<offset>0.0</offset>
			</joint>
		</transmission>
		<joint name="gripper_left_finger_joint">
			<command_interface name="position"/>
			<state_interface name="position"/>
			<state_interface name="velocity"/>
			<state_interface name="effort"/>
		</joint>
		<transmission name="gripper_left_finger_trans">
			<plugin>transmission_interface/SimpleTransmission</plugin>
			<actuator name="gripper_left_finger_actuator" role="actuator1"/>
			<joint name="gripper_left_finger_joint" role="joint1">
				<mechanical_reduction>1.0</mechanical_reduction>
			</joint>
		</transmission>
		<joint name="gripper_right_finger_joint">
			<command_interface name="position"/>
			<state_interface name="position"/>
			<state_interface name="velocity"/>
			<state_interface name="effort"/>
		</joint>
		<transmission name="gripper_right_finger_trans">
			<plugin>transmission_interface/SimpleTransmission</plugin>
			<actuator name="gripper_right_finger_actuator" role="actuator1"/>
			<joint name="gripper_right_finger_joint" role="joint1">
				<mechanical_reduction>1.0</mechanical_reduction>
			</joint>
		</transmission>
		<sensor name="wrist_ft_joint_force_torque">
			<state_interface name="force.x"/>
			<state_interface name="force.y"/>
			<state_interface name="force.z"/>
			<state_interface name="torque.x"/>
			<state_interface name="torque.y"/>
			<state_interface name="torque.z"/>
		</sensor>
	</ros2_control>
	<material name="Blue">
		<color rgba="0.0 0.0 0.8 1.0"/>
	</material>
	<material name="Green">
		<color rgba="0.0 0.8 0.0 1.0"/>
	</material>
	<material name="Grey">
		<color rgba="0.7 0.7 0.7 1.0"/>
	</material>
	<material name="LightGrey">
		<color rgba="0.9 0.9 0.9 1.0"/>
	</material>
	<material name="DarkGrey">
		<color rgba="0.1 0.1 0.1 1.0"/>
	</material>
	<material name="Red">
		<color rgba="0.8 0.0 0.0 1.0"/>
	</material>
	<material name="White">
		<color rgba="1.0 1.0 1.0 1.0"/>
	</material>
	<material name="Yellow">
		<color rgba="0.96 0.88 0.14 1.0"/>
	</material>
	<material name="Orange">
		<color rgba="1.0 0.69 0.0 1.0"/>
	</material>
	<material name="Black">
		<color rgba="0.0 0.0 0.0 1.0"/>
	</material>
	<material name="FlatBlack">
		<color rgba="0.09 0.09 0.09 1.0"/>
	</material>
	<link name="base_laser_link" type="laser">
		<inertial>
			<origin rpy="0 0 0" xyz="-0.02559000000 -0.00056000000 -0.05732000000"/>
			<mass value="0.28922000000"/>
			<inertia ixx="0.00002628919" ixy="0.00000024298" ixz="-0.00000368129" iyy="0.00003374542" iyz="-0.00000001330" izz="0.00005832599"/>
		</inertial>
		<visual>
			<origin rpy="0 0 0" xyz="0 0 0"/>
			<geometry>
				<mesh filename="package://pmb2_description/meshes/sensors/sick_tim551.stl"/>
			</geometry>
			<material name="DarkGrey"/>
		</visual>
	</link>
	<joint name="base_laser_joint" type="fixed">
		<axis xyz="0 1 0"/>
		<origin rpy="0 0 0" xyz="0.202 0.0 -0.004"/>
		<parent link="base_link"/>
		<child link="base_laser_link"/>
	</joint>
	<gazebo reference="base_laser_link">
		<sensor name="base_laser" type="ray">
			<pose>0 0 0 0 0 0</pose>
			<update_rate>10</update_rate>
			<visualize>true</visualize>
			<ray>
				<scan>
					<horizontal>
						<!-- 818 (270/0.33) steps in 270deg fov -->
						<samples>666.5185185185185</samples>
						<resolution>1</resolution>
						<!-- not the sensor resolution; just 1 -->
						<min_angle>-1.9198621771937625</min_angle>
						<max_angle>1.9198621771937625</max_angle>
					</horizontal>
				</scan>
				<range>
					<min>0.05</min>
					<max>25.0</max>
					<resolution>0.001</resolution>
				</range>
				<noise>
					<type>gaussian</type>
					<mean>0.0</mean>
					<stddev>0.06</stddev>
				</noise>
			</ray>
			<plugin filename="libgazebo_ros_ray_sensor.so" name="bytes_laserscan">
				<ros>
					<remapping>~/out:=scan_raw</remapping>
				</ros>
				<output_type>sensor_msgs/LaserScan</output_type>
				<frame_name>base_laser_link</frame_name>
			</plugin>
		</sensor>
		<material>Gazebo/DarkGrey</material>
	</gazebo>
	<link name="base_sonar_03_link">
		<inertial>
			<origin rpy="0 0 0" xyz="0 0 0"/>
			<mass value="0.001"/>
			<inertia ixx="0.000001" ixy="0" ixz="0" iyy="0.000001" iyz="0" izz="0.000001"/>
		</inertial>
		<visual>
			<origin rpy="0 0 0" xyz="0 0 0"/>
			<geometry>
				<mesh filename="package://pmb2_description/meshes/sensors/srf05.stl"/>
			</geometry>
			<material name="DarkGrey"/>
		</visual>
	</link>
	<joint name="base_sonar_03_joint" type="fixed">
		<origin rpy="0 0 2.356194490192345" xyz="-0.183 0.183 0.173"/>
		<axis xyz="0 0 1"/>
		<parent link="base_link"/>
		<child link="base_sonar_03_link"/>
	</joint>
	<gazebo reference="base_sonar_03_link">
		<sensor name="base_sonar_03" type="ray">
			<pose>0 0 0 0 0 0</pose>
			<update_rate>5</update_rate>
			<visualize>false</visualize>
			<ray>
				<scan>
					<horizontal>
						<samples>5</samples>
						<resolution>1</resolution>
						<min_angle>-0.25</min_angle>
						<max_angle>0.25</max_angle>
					</horizontal>
					<vertical>
						<samples>5</samples>
						<resolution>1</resolution>
						<min_angle>-0.25</min_angle>
						<max_angle>0.25</max_angle>
					</vertical>
				</scan>
				<range>
					<min>0.02</min>
					<max>1.0</max>
					<resolution>0.01</resolution>
				</range>
				<noise>
					<type>gaussian</type>
					<mean>0.0</mean>
					<stddev>0.005</stddev>
				</noise>
			</ray>
			<plugin filename="libgazebo_ros_ray_sensor.so" name="base_sonar_03_gazebo_ros_range">
				<ros>
					<namespace>distance</namespace>
					<remapping>~/out:=sonar_base</remapping>
				</ros>
				<output_type>sensor_msgs/Range</output_type>
				<radiation_type>ultrasound</radiation_type>
				<frame_name>base_sonar_03_link</frame_name>
			</plugin>
		</sensor>
		<material>Gazebo/DarkGrey</material>
	</gazebo>
	<link name="base_sonar_02_link">
		<inertial>
			<origin rpy="0 0 0" xyz="0 0 0"/>
			<mass value="0.001"/>
			<inertia ixx="0.000001" ixy="0" ixz="0" iyy="0.000001" iyz="0" izz="0.000001"/>
		</inertial>
		<visual>
			<origin rpy="0 0 0" xyz="0 0 0"/>
			<geometry>
				<mesh filename="package://pmb2_description/meshes/sensors/srf05.stl"/>
			</geometry>
			<material name="DarkGrey"/>
		</visual>
	</link>
	<joint name="base_sonar_02_joint" type="fixed">
		<origin rpy="0 0 3.141592653589793" xyz="-0.259 0.0 0.173"/>
		<axis xyz="0 0 1"/>
		<parent link="base_link"/>
		<child link="base_sonar_02_link"/>
	</joint>
	<gazebo reference="base_sonar_02_link">
		<sensor name="base_sonar_02" type="ray">
			<pose>0 0 0 0 0 0</pose>
			<update_rate>5</update_rate>
			<visualize>false</visualize>
			<ray>
				<scan>
					<horizontal>
						<samples>5</samples>
						<resolution>1</resolution>
						<min_angle>-0.25</min_angle>
						<max_angle>0.25</max_angle>
					</horizontal>
					<vertical>
						<samples>5</samples>
						<resolution>1</resolution>
						<min_angle>-0.25</min_angle>
						<max_angle>0.25</max_angle>
					</vertical>
				</scan>
				<range>
					<min>0.02</min>
					<max>1.0</max>
					<resolution>0.01</resolution>
				</range>
				<noise>
					<type>gaussian</type>
					<mean>0.0</mean>
					<stddev>0.005</stddev>
				</noise>
			</ray>
			<plugin filename="libgazebo_ros_ray_sensor.so" name="base_sonar_02_gazebo_ros_range">
				<ros>
					<namespace>distance</namespace>
					<remapping>~/out:=sonar_base</remapping>
				</ros>
				<output_type>sensor_msgs/Range</output_type>
				<radiation_type>ultrasound</radiation_type>
				<frame_name>base_sonar_02_link</frame_name>
			</plugin>
		</sensor>
		<material>Gazebo/DarkGrey</material>
	</gazebo>
	<link name="base_sonar_01_link">
		<inertial>
			<origin rpy="0 0 0" xyz="0 0 0"/>
			<mass value="0.001"/>
			<inertia ixx="0.000001" ixy="0" ixz="0" iyy="0.000001" iyz="0" izz="0.000001"/>
		</inertial>
		<visual>
			<origin rpy="0 0 0" xyz="0 0 0"/>
			<geometry>
				<mesh filename="package://pmb2_description/meshes/sensors/srf05.stl"/>
			</geometry>
			<material name="DarkGrey"/>
		</visual>
	</link>
	<joint name="base_sonar_01_joint" type="fixed">
		<origin rpy="0 0 3.9269908169872414" xyz="-0.183 -0.183 0.173"/>
		<axis xyz="0 0 1"/>
		<parent link="base_link"/>
		<child link="base_sonar_01_link"/>
	</joint>
	<gazebo reference="base_sonar_01_link">
		<sensor name="base_sonar_01" type="ray">
			<pose>0 0 0 0 0 0</pose>
			<update_rate>5</update_rate>
			<visualize>false</visualize>
			<ray>
				<scan>
					<horizontal>
						<samples>5</samples>
						<resolution>1</resolution>
						<min_angle>-0.25</min_angle>
						<max_angle>0.25</max_angle>
					</horizontal>
					<vertical>
						<samples>5</samples>
						<resolution>1</resolution>
						<min_angle>-0.25</min_angle>
						<max_angle>0.25</max_angle>
					</vertical>
				</scan>
				<range>
					<min>0.02</min>
					<max>1.0</max>
					<resolution>0.01</resolution>
				</range>
				<noise>
					<type>gaussian</type>
					<mean>0.0</mean>
					<stddev>0.005</stddev>
				</noise>
			</ray>
			<plugin filename="libgazebo_ros_ray_sensor.so" name="base_sonar_01_gazebo_ros_range">
				<ros>
					<namespace>distance</namespace>
					<remapping>~/out:=sonar_base</remapping>
				</ros>
				<output_type>sensor_msgs/Range</output_type>
				<radiation_type>ultrasound</radiation_type>
				<frame_name>base_sonar_01_link</frame_name>
			</plugin>
		</sensor>
		<material>Gazebo/DarkGrey</material>
	</gazebo>
	<link name="base_mic_front_left_link"/>
	<joint name="base_mic_front_left_joint" type="fixed">
		<origin rpy="0 0 0" xyz="0.23182 0.03902 0.195"/>
		<child link="base_mic_front_left_link"/>
		<parent link="base_link"/>
	</joint>
	<link name="base_mic_front_right_link"/>
	<joint name="base_mic_front_right_joint" type="fixed">
		<origin rpy="0 0 0" xyz="0.23182 -0.03902 0.195"/>
		<child link="base_mic_front_right_link"/>
		<parent link="base_link"/>
	</joint>
	<link name="base_mic_back_left_link"/>
	<joint name="base_mic_back_left_joint" type="fixed">
		<origin rpy="0 0 0" xyz="-0.1082 -0.0599 0.195"/>
		<child link="base_mic_back_left_link"/>
		<parent link="base_link"/>
	</joint>
	<link name="base_mic_back_right_link"/>
	<joint name="base_mic_back_right_joint" type="fixed">
		<origin rpy="0 0 0" xyz="-0.1082 -0.13789 0.195"/>
		<child link="base_mic_back_right_link"/>
		<parent link="base_link"/>
	</joint>
	<!-- Base -->
	<link name="base_link">
		<inertial>
			<origin rpy="0 0 0" xyz="-0.00000106 0.00000109 0.0000387"/>
			<mass value="28.26649"/>
			<inertia ixx="0.465408937" ixy="0.002160024" ixz="-0.001760255" iyy="0.483193291" iyz="-0.000655952" izz="0.550939703"/>
		</inertial>
		<visual>
			<origin rpy="0 0 0" xyz="0 0 0"/>
			<geometry>
				<mesh filename="package://pmb2_description/meshes/base/base.stl"/>
			</geometry>
			<material name="White"/>
		</visual>
		<collision>
			<origin rpy="0 0 0" xyz="0 0 0"/>
			<geometry>
				<mesh filename="package://pmb2_description/meshes/base/high_resolution/base_collision.stl"/>
			</geometry>
			<material name="White"/>
		</collision>
	</link>
	<gazebo reference="base_link">
		<material>Gazebo/White</material>
	</gazebo>
	<!-- Base footprint -->
	<link name="base_footprint"/>
	<joint name="base_footprint_joint" type="fixed">
		<origin rpy="0 0 0" xyz="0 0 0.0985"/>
		<child link="base_link"/>
		<parent link="base_footprint"/>
	</joint>
	<!-- gazebo parameters are given here for base_link thru base_footprint -->
	<gazebo reference="base_footprint">
		<kp>100000000.0</kp>
		<kd>10.0</kd>
		<mu1>0.1</mu1>
		<mu2>0.1</mu2>
		<fdir1>1 0 0</fdir1>
		<maxVel>10.0</maxVel>
		<minDepth>0.0005</minDepth>
		<laserRetro>0</laserRetro>
	</gazebo>
	<link name="base_cover_link">
		<inertial>
			<origin rpy="0 0 0" xyz="0.22414000000 0.00002000000 0.04681000000"/>
			<mass value="0.25821000000"/>
			<inertia ixx="0.00023719188" ixy="0.00000006119" ixz="-0.00000011799" iyy="0.00028335052" iyz="0.00000000774" izz="0.00038497063"/>
		</inertial>
		<visual>
			<origin rpy="0 0 0" xyz="0 0 0"/>
			<geometry>
				<mesh filename="package://pmb2_description/meshes/base/base_ring.stl"/>
			</geometry>
			<material name="Orange"/>
		</visual>
	</link>
	<joint name="cover_joint" type="fixed">
		<parent link="base_footprint"/>
		<child link="base_cover_link"/>
		<origin rpy="0 0 0" xyz="0 0 0.13"/>
	</joint>
	<gazebo reference="base_cover_link">
		<material>Gazebo/Orange</material>
	</gazebo>
	<link name="base_antenna_left_link">
		<inertial>
			<origin rpy="0 0 0" xyz="0 0 0"/>
			<mass value="0.000001"/>
			<inertia ixx="0.00000002371" ixy="0.00000006119" ixz="0.00000001179" iyy="0.00000002833" iyz="0.00000000774" izz="0.00000003849"/>
		</inertial>
		<visual>
			<origin rpy="0 0 0" xyz="0 0 0"/>
			<geometry>
				<mesh filename="package://pmb2_description/meshes/objects/antenna.stl"/>
			</geometry>
			<material name="Black"/>
		</visual>
		<collision>
			<origin rpy="0 0 0" xyz="0 0 0.085"/>
			<geometry>
				<cylinder length="0.17" radius="0.005"/>
			</geometry>
			<material name="Black"/>
		</collision>
	</link>
	<gazebo reference="base_antenna_left_link">
		<material>Gazebo/Black</material>
	</gazebo>
	<joint name="base_antenna_left_joint" type="fixed">
		<parent link="base_link"/>
		<child link="base_antenna_left_link"/>
		<origin rpy="0 0 0" xyz="-0.201 0.1062 0.195"/>
	</joint>
	<link name="base_antenna_right_link">
		<inertial>
			<origin rpy="0 0 0" xyz="0 0 0"/>
			<mass value="0.000001"/>
			<inertia ixx="0.00000002371" ixy="0.00000006119" ixz="0.00000001179" iyy="0.00000002833" iyz="0.00000000774" izz="0.00000003849"/>
		</inertial>
		<visual>
			<origin rpy="0 0 0" xyz="0 0 0"/>
			<geometry>
				<mesh filename="package://pmb2_description/meshes/objects/antenna.stl"/>
			</geometry>
			<material name="Black"/>
		</visual>
		<collision>
			<origin rpy="0 0 0" xyz="0 0 0.085"/>
			<geometry>
				<cylinder length="0.17" radius="0.005"/>
			</geometry>
			<material name="Black"/>
		</collision>
	</link>
	<gazebo reference="base_antenna_right_link">
		<material>Gazebo/Black</material>
	</gazebo>
	<joint name="base_antenna_right_joint" type="fixed">
		<parent link="base_link"/>
		<child link="base_antenna_right_link"/>
		<origin rpy="0 0 0" xyz="-0.201 -0.1062 0.195"/>
	</joint>
	<link name="base_imu_link">
		<inertial>
			<mass value="0.01"/>
			<origin xyz="0 0 0"/>
			<inertia ixx="0.000001" ixy="0" ixz="0" iyy="0.000001" iyz="0" izz="0.000001"/>
		</inertial>
		<!--visual>\n        <origin rpy="0 0 0" xyz="0 0 0"/>\n        <geometry>\n          <box size="0.01 0.01 0.01"/>\n        </geometry>\n      </visual-->
	</link>
	<joint name="base_imu_joint" type="fixed">
		<parent link="base_link"/>
		<child link="base_imu_link"/>
		<origin rpy="0 0 -1.5707963267948966" xyz="0.10171 0 0.11282"/>
	</joint>
	<gazebo reference="base_imu_link">
		<sensor name="base_imu_sensor" type="imu">
			<always_on>1</always_on>
			<update_rate>100.0</update_rate>
			<imu>
				<noise>
					<type>gaussian</type>
					<rate>
						<mean>0.0</mean>
						<stddev>2e-4</stddev>
						<bias_mean>0.0000075</bias_mean>
						<bias_stddev>0.0000008</bias_stddev>
					</rate>
					<accel>
						<mean>0.0</mean>
						<stddev>1.7e-2</stddev>
						<bias_mean>0.1</bias_mean>
						<bias_stddev>0.001</bias_stddev>
					</accel>
				</noise>
			</imu>
		</sensor>
	</gazebo>
	<link name="wheel_right_link">
		<inertial>
			<origin rpy="0 0 0" xyz="0 0 -0.00207"/>
			<mass value="1.82362"/>
			<inertia ixx="0.00499743171" ixy="4.464e-08" ixz="-0.00000002245" iyy="0.00499741733" iyz="-1.64e-09" izz="0.00839239692"/>
		</inertial>
		<visual>
			<origin rpy="-0.0 0 0" xyz="0 0 0"/>
			<geometry>
				<mesh filename="package://pmb2_description/meshes/wheels/wheel.stl"/>
			</geometry>
			<material name="DarkGrey"/>
		</visual>
		<collision>
			<origin rpy="0 0 0" xyz="0 0 0"/>
			<geometry>
				<sphere radius="0.0985"/>
				<!-- length="${width}"/>-->
			</geometry>
		</collision>
	</link>
	<joint name="wheel_right_joint" type="continuous">
		<parent link="base_link"/>
		<child link="wheel_right_link"/>
		<origin rpy="-1.5707963267948966 0 0" xyz="0 -0.2022 0.0"/>
		<axis xyz="0 0 1"/>
		<limit effort="6.0" velocity="10.152284263959391"/>
		<dynamics damping="1.0" friction="2.0"/>
	</joint>
	<!-- Contact model for the wheel surface -->
	<gazebo reference="wheel_right_link">
		<kp>1000000.0</kp>
		<kd>100.0</kd>
		<friction>
			<ode>
				<mu>1.0</mu>
				<mu2>1.0</mu2>
			</ode>
		</friction>
		<!--<fdir1>1 0 0</fdir1>-->
		<max_vel>1.0</max_vel>
		<min_depth>0.002</min_depth>
		<material>Gazebo/DarkGrey</material>
	</gazebo>
	<gazebo reference="wheel_{side}_joint">
		<physics>
			<ode>
				<implicit_spring_damper>1</implicit_spring_damper>
			</ode>
		</physics>
	</gazebo>
	<link name="wheel_left_link">
		<inertial>
			<origin rpy="0 0 0" xyz="0 0 0.00207"/>
			<mass value="1.82362"/>
			<inertia ixx="0.00499743171" ixy="-4.464e-08" ixz="-0.00000002245" iyy="0.00499741733" iyz="1.64e-09" izz="0.00839239692"/>
		</inertial>
		<visual>
			<origin rpy="-3.141592653589793 0 0" xyz="0 0 0"/>
			<geometry>
				<mesh filename="package://pmb2_description/meshes/wheels/wheel.stl"/>
			</geometry>
			<material name="DarkGrey"/>
		</visual>
		<collision>
			<origin rpy="0 0 0" xyz="0 0 0"/>
			<geometry>
				<sphere radius="0.0985"/>
				<!-- length="${width}"/>-->
			</geometry>
		</collision>
	</link>
	<joint name="wheel_left_joint" type="continuous">
		<parent link="base_link"/>
		<child link="wheel_left_link"/>
		<origin rpy="-1.5707963267948966 0 0" xyz="0 0.2022 0.0"/>
		<axis xyz="0 0 1"/>
		<limit effort="6.0" velocity="10.152284263959391"/>
		<dynamics damping="1.0" friction="2.0"/>
	</joint>
	<!-- Contact model for the wheel surface -->
	<gazebo reference="wheel_left_link">
		<kp>1000000.0</kp>
		<kd>100.0</kd>
		<friction>
			<ode>
				<mu>1.0</mu>
				<mu2>1.0</mu2>
			</ode>
		</friction>
		<!--<fdir1>1 0 0</fdir1>-->
		<max_vel>1.0</max_vel>
		<min_depth>0.002</min_depth>
		<material>Gazebo/DarkGrey</material>
	</gazebo>
	<gazebo reference="wheel_{side}_joint">
		<physics>
			<ode>
				<implicit_spring_damper>1</implicit_spring_damper>
			</ode>
		</physics>
	</gazebo>
	<link name="caster_front_right_1_link">
		<inertial>
			<origin rpy="0 0 0" xyz="-0.00634599 0.00005347 -0.02037519"/>
			<mass value="0.05144761"/>
			<inertia ixx="0.00001513" ixy="-0.00000003" ixz="0.00000267" iyy="0.00001309" iyz="-0.00000005" izz="0.00001198"/>
		</inertial>
		<visual>
			<origin rpy="0 0 0" xyz="0 0 0"/>
			<geometry>
				<mesh filename="package://pmb2_description/meshes/wheels/caster_1.stl"/>
			</geometry>
			<material name="Grey"/>
		</visual>
		<!--collision>\n        <origin xyz="0 0 0" rpy="0 0 0"/>\n        <geometry>\n          <cylinder radius="${radius}" length="${width}"/>\n        </geometry>\n      </collision-->
	</link>
	<link name="caster_front_right_2_link">
		<inertial>
			<origin rpy="0 0 0" xyz="0 0 0"/>
			<mass value="0.08855784"/>
			<inertia ixx="0.00001075" ixy="0" ixz="0" iyy="0.00001541" iyz="0" izz="0.00001075"/>
		</inertial>
		<visual>
			<origin rpy="0 0 0" xyz="0 0 0"/>
			<geometry>
				<mesh filename="package://pmb2_description/meshes/wheels/caster_2.stl"/>
			</geometry>
			<material name="DarkGrey"/>
		</visual>
		<collision>
			<origin rpy="0 0 0" xyz="0 0 0"/>
			<geometry>
				<sphere radius="0.025"/>
			</geometry>
		</collision>
	</link>
	<joint name="caster_front_right_1_joint" type="continuous">
		<parent link="base_link"/>
		<child link="caster_front_right_1_link"/>
		<origin rpy="0 0 0" xyz="0.1695 -0.102 -0.0335"/>
		<axis xyz="0 0 1"/>
		<dynamics damping="0.015" friction="0.0"/>
	</joint>
	<joint name="caster_front_right_2_joint" type="continuous">
		<parent link="caster_front_right_1_link"/>
		<child link="caster_front_right_2_link"/>
		<origin rpy="-1.5707963267948966 0 0" xyz="-0.016 0.0000 -0.040"/>
		<axis xyz="0 0 1"/>
		<dynamics damping="0.015" friction="0.0"/>
	</joint>
	<!-- Contact model for the caster wheel surface -->
	<gazebo reference="caster_front_right_1_link">
		<kp>1000000.0</kp>
		<kd>10000.0</kd>
		<friction>
			<ode>
				<mu>1.0</mu>
				<mu2>1.0</mu2>
			</ode>
		</friction>
		<!--<fdir1>1 0 0</fdir1>-->
		<max_vel>1.0</max_vel>
		<min_depth>0.005</min_depth>
		<material>Gazebo/DarkGrey</material>
	</gazebo>
	<gazebo reference="caster_front_right_2_link">
		<kp>1000000.0</kp>
		<kd>10000.0</kd>
		<friction>
			<ode>
				<mu>1.0</mu>
				<mu2>1.0</mu2>
			</ode>
		</friction>
		<!--<fdir1>1 0 0</fdir1>-->
		<max_vel>1.0</max_vel>
		<min_depth>0.005</min_depth>
		<material>Gazebo/DarkGrey</material>
	</gazebo>
	<gazebo reference="caster_{side}_1_joint">
		<physics>
			<ode>
				<implicit_spring_damper>0</implicit_spring_damper>
			</ode>
		</physics>
	</gazebo>
	<gazebo reference="caster_{side}_2_joint">
		<physics>
			<ode>
				<implicit_spring_damper>0</implicit_spring_damper>
			</ode>
		</physics>
	</gazebo>
	<link name="caster_front_left_1_link">
		<inertial>
			<origin rpy="0 0 0" xyz="-0.00634599 0.00005347 -0.02037519"/>
			<mass value="0.05144761"/>
			<inertia ixx="0.00001513" ixy="-0.00000003" ixz="0.00000267" iyy="0.00001309" iyz="-0.00000005" izz="0.00001198"/>
		</inertial>
		<visual>
			<origin rpy="0 0 0" xyz="0 0 0"/>
			<geometry>
				<mesh filename="package://pmb2_description/meshes/wheels/caster_1.stl"/>
			</geometry>
			<material name="Grey"/>
		</visual>
		<!--collision>\n        <origin xyz="0 0 0" rpy="0 0 0"/>\n        <geometry>\n          <cylinder radius="${radius}" length="${width}"/>\n        </geometry>\n      </collision-->
	</link>
	<link name="caster_front_left_2_link">
		<inertial>
			<origin rpy="0 0 0" xyz="0 0 0"/>
			<mass value="0.08855784"/>
			<inertia ixx="0.00001075" ixy="0" ixz="0" iyy="0.00001541" iyz="0" izz="0.00001075"/>
		</inertial>
		<visual>
			<origin rpy="0 0 0" xyz="0 0 0"/>
			<geometry>
				<mesh filename="package://pmb2_description/meshes/wheels/caster_2.stl"/>
			</geometry>
			<material name="DarkGrey"/>
		</visual>
		<collision>
			<origin rpy="0 0 0" xyz="0 0 0"/>
			<geometry>
				<sphere radius="0.025"/>
			</geometry>
		</collision>
	</link>
	<joint name="caster_front_left_1_joint" type="continuous">
		<parent link="base_link"/>
		<child link="caster_front_left_1_link"/>
		<origin rpy="0 0 0" xyz="0.1695 0.102 -0.0335"/>
		<axis xyz="0 0 1"/>
		<dynamics damping="0.015" friction="0.0"/>
	</joint>
	<joint name="caster_front_left_2_joint" type="continuous">
		<parent link="caster_front_left_1_link"/>
		<child link="caster_front_left_2_link"/>
		<origin rpy="-1.5707963267948966 0 0" xyz="-0.016 0.0000 -0.040"/>
		<axis xyz="0 0 1"/>
		<dynamics damping="0.015" friction="0.0"/>
	</joint>
	<!-- Contact model for the caster wheel surface -->
	<gazebo reference="caster_front_left_1_link">
		<kp>1000000.0</kp>
		<kd>10000.0</kd>
		<friction>
			<ode>
				<mu>1.0</mu>
				<mu2>1.0</mu2>
			</ode>
		</friction>
		<!--<fdir1>1 0 0</fdir1>-->
		<max_vel>1.0</max_vel>
		<min_depth>0.005</min_depth>
		<material>Gazebo/DarkGrey</material>
	</gazebo>
	<gazebo reference="caster_front_left_2_link">
		<kp>1000000.0</kp>
		<kd>10000.0</kd>
		<friction>
			<ode>
				<mu>1.0</mu>
				<mu2>1.0</mu2>
			</ode>
		</friction>
		<!--<fdir1>1 0 0</fdir1>-->
		<max_vel>1.0</max_vel>
		<min_depth>0.005</min_depth>
		<material>Gazebo/DarkGrey</material>
	</gazebo>
	<gazebo reference="caster_{side}_1_joint">
		<physics>
			<ode>
				<implicit_spring_damper>0</implicit_spring_damper>
			</ode>
		</physics>
	</gazebo>
	<gazebo reference="caster_{side}_2_joint">
		<physics>
			<ode>
				<implicit_spring_damper>0</implicit_spring_damper>
			</ode>
		</physics>
	</gazebo>
	<link name="caster_back_right_1_link">
		<inertial>
			<origin rpy="0 0 0" xyz="-0.00634599 0.00005347 -0.02037519"/>
			<mass value="0.05144761"/>
			<inertia ixx="0.00001513" ixy="-0.00000003" ixz="0.00000267" iyy="0.00001309" iyz="-0.00000005" izz="0.00001198"/>
		</inertial>
		<visual>
			<origin rpy="0 0 0" xyz="0 0 0"/>
			<geometry>
				<mesh filename="package://pmb2_description/meshes/wheels/caster_1.stl"/>
			</geometry>
			<material name="Grey"/>
		</visual>
		<!--collision>\n        <origin xyz="0 0 0" rpy="0 0 0"/>\n        <geometry>\n          <cylinder radius="${radius}" length="${width}"/>\n        </geometry>\n      </collision-->
	</link>
	<link name="caster_back_right_2_link">
		<inertial>
			<origin rpy="0 0 0" xyz="0 0 0"/>
			<mass value="0.08855784"/>
			<inertia ixx="0.00001075" ixy="0" ixz="0" iyy="0.00001541" iyz="0" izz="0.00001075"/>
		</inertial>
		<visual>
			<origin rpy="0 0 0" xyz="0 0 0"/>
			<geometry>
				<mesh filename="package://pmb2_description/meshes/wheels/caster_2.stl"/>
			</geometry>
			<material name="DarkGrey"/>
		</visual>
		<collision>
			<origin rpy="0 0 0" xyz="0 0 0"/>
			<geometry>
				<sphere radius="0.025"/>
			</geometry>
		</collision>
	</link>
	<joint name="caster_back_right_1_joint" type="continuous">
		<parent link="base_link"/>
		<child link="caster_back_right_1_link"/>
		<origin rpy="0 0 0" xyz="-0.17350000000000002 -0.102 -0.0335"/>
		<axis xyz="0 0 1"/>
		<dynamics damping="0.015" friction="0.0"/>
	</joint>
	<joint name="caster_back_right_2_joint" type="continuous">
		<parent link="caster_back_right_1_link"/>
		<child link="caster_back_right_2_link"/>
		<origin rpy="-1.5707963267948966 0 0" xyz="-0.016 0.0000 -0.040"/>
		<axis xyz="0 0 1"/>
		<dynamics damping="0.015" friction="0.0"/>
	</joint>
	<!-- Contact model for the caster wheel surface -->
	<gazebo reference="caster_back_right_1_link">
		<kp>1000000.0</kp>
		<kd>10000.0</kd>
		<friction>
			<ode>
				<mu>1.0</mu>
				<mu2>1.0</mu2>
			</ode>
		</friction>
		<!--<fdir1>1 0 0</fdir1>-->
		<max_vel>1.0</max_vel>
		<min_depth>0.005</min_depth>
		<material>Gazebo/DarkGrey</material>
	</gazebo>
	<gazebo reference="caster_back_right_2_link">
		<kp>1000000.0</kp>
		<kd>10000.0</kd>
		<friction>
			<ode>
				<mu>1.0</mu>
				<mu2>1.0</mu2>
			</ode>
		</friction>
		<!--<fdir1>1 0 0</fdir1>-->
		<max_vel>1.0</max_vel>
		<min_depth>0.005</min_depth>
		<material>Gazebo/DarkGrey</material>
	</gazebo>
	<gazebo reference="caster_{side}_1_joint">
		<physics>
			<ode>
				<implicit_spring_damper>0</implicit_spring_damper>
			</ode>
		</physics>
	</gazebo>
	<gazebo reference="caster_{side}_2_joint">
		<physics>
			<ode>
				<implicit_spring_damper>0</implicit_spring_damper>
			</ode>
		</physics>
	</gazebo>
	<link name="caster_back_left_1_link">
		<inertial>
			<origin rpy="0 0 0" xyz="-0.00634599 0.00005347 -0.02037519"/>
			<mass value="0.05144761"/>
			<inertia ixx="0.00001513" ixy="-0.00000003" ixz="0.00000267" iyy="0.00001309" iyz="-0.00000005" izz="0.00001198"/>
		</inertial>
		<visual>
			<origin rpy="0 0 0" xyz="0 0 0"/>
			<geometry>
				<mesh filename="package://pmb2_description/meshes/wheels/caster_1.stl"/>
			</geometry>
			<material name="Grey"/>
		</visual>
		<!--collision>\n        <origin xyz="0 0 0" rpy="0 0 0"/>\n        <geometry>\n          <cylinder radius="${radius}" length="${width}"/>\n        </geometry>\n      </collision-->
	</link>
	<link name="caster_back_left_2_link">
		<inertial>
			<origin rpy="0 0 0" xyz="0 0 0"/>
			<mass value="0.08855784"/>
			<inertia ixx="0.00001075" ixy="0" ixz="0" iyy="0.00001541" iyz="0" izz="0.00001075"/>
		</inertial>
		<visual>
			<origin rpy="0 0 0" xyz="0 0 0"/>
			<geometry>
				<mesh filename="package://pmb2_description/meshes/wheels/caster_2.stl"/>
			</geometry>
			<material name="DarkGrey"/>
		</visual>
		<collision>
			<origin rpy="0 0 0" xyz="0 0 0"/>
			<geometry>
				<sphere radius="0.025"/>
			</geometry>
		</collision>
	</link>
	<joint name="caster_back_left_1_joint" type="continuous">
		<parent link="base_link"/>
		<child link="caster_back_left_1_link"/>
		<origin rpy="0 0 0" xyz="-0.17350000000000002 0.102 -0.0335"/>
		<axis xyz="0 0 1"/>
		<dynamics damping="0.015" friction="0.0"/>
	</joint>
	<joint name="caster_back_left_2_joint" type="continuous">
		<parent link="caster_back_left_1_link"/>
		<child link="caster_back_left_2_link"/>
		<origin rpy="-1.5707963267948966 0 0" xyz="-0.016 0.0000 -0.040"/>
		<axis xyz="0 0 1"/>
		<dynamics damping="0.015" friction="0.0"/>
	</joint>
	<!-- Contact model for the caster wheel surface -->
	<gazebo reference="caster_back_left_1_link">
		<kp>1000000.0</kp>
		<kd>10000.0</kd>
		<friction>
			<ode>
				<mu>1.0</mu>
				<mu2>1.0</mu2>
			</ode>
		</friction>
		<!--<fdir1>1 0 0</fdir1>-->
		<max_vel>1.0</max_vel>
		<min_depth>0.005</min_depth>
		<material>Gazebo/DarkGrey</material>
	</gazebo>
	<gazebo reference="caster_back_left_2_link">
		<kp>1000000.0</kp>
		<kd>10000.0</kd>
		<friction>
			<ode>
				<mu>1.0</mu>
				<mu2>1.0</mu2>
			</ode>
		</friction>
		<!--<fdir1>1 0 0</fdir1>-->
		<max_vel>1.0</max_vel>
		<min_depth>0.005</min_depth>
		<material>Gazebo/DarkGrey</material>
	</gazebo>
	<gazebo reference="caster_{side}_1_joint">
		<physics>
			<ode>
				<implicit_spring_damper>0</implicit_spring_damper>
			</ode>
		</physics>
	</gazebo>
	<gazebo reference="caster_{side}_2_joint">
		<physics>
			<ode>
				<implicit_spring_damper>0</implicit_spring_damper>
			</ode>
		</physics>
	</gazebo>
	<!-- Bottom fixed part of column -->
	<link name="torso_fixed_link">
		<inertial>
			<origin rpy="0.00000 0.00000 0.00000" xyz="0.02435 -0.00464 0.15900"/>
			<mass value="14.01360"/>
			<inertia ixx="0.38341100000" ixy="0.00036400000" ixz="-0.02438900000" iyy="0.40577300000" iyz="-0.00078200000" izz="0.07699800000"/>
		</inertial>
		<visual>
			<origin rpy="0 0 0" xyz="0 0 0"/>
			<geometry>
				<mesh filename="package://tiago_description/meshes/torso/torso_fix.stl" scale="1 1 1"/>
			</geometry>
			<material name="LightGrey"/>
		</visual>
		<collision>
			<origin rpy="0 0 0" xyz="0.085 0.0 0.02"/>
			<geometry>
				<box size="0.4 0.25 0.04"/>
			</geometry>
		</collision>
		<collision>
			<origin rpy="0 0 0" xyz="0 0 0.05"/>
			<geometry>
				<box size="0.25 0.25 0.1"/>
			</geometry>
		</collision>
	</link>
	<joint name="torso_fixed_joint" type="fixed">
		<origin rpy="0 0 0" xyz="-0.062 0.0 0.193"/>
		<parent link="base_link"/>
		<child link="torso_fixed_link"/>
		<axis xyz="0 0 0"/>
	</joint>
	<!-- Middle extending  -->
	<link name="torso_fixed_column_link">
		<inertial>
			<origin rpy="0 0 0" xyz="0 0 0"/>
			<mass value="0.01"/>
			<inertia ixx="0.000001" ixy="0" ixz="0" iyy="0.000001" iyz="0" izz="0.000001"/>
		</inertial>
		<visual>
			<origin rpy="0 0 0" xyz="0 0 0.275"/>
			<geometry>
				<box size="0.18 0.2 0.55"/>
			</geometry>
			<material name="DarkGrey"/>
		</visual>
		<collision>
			<origin rpy="0 0 0" xyz="0 0 0.275"/>
			<geometry>
				<box size="0.23 0.23 0.55"/>
			</geometry>
			<material name="DarkGrey"/>
		</collision>
	</link>
	<gazebo reference="torso_fixed_column_link">
		<material>Gazebo/DarkGrey</material>
	</gazebo>
	<joint name="torso_fixed_column_joint" type="fixed">
		<origin rpy="0 0 0" xyz="-0.062 0 0.195"/>
		<parent link="base_link"/>
		<child link="torso_fixed_column_link"/>
		<axis xyz="0 0 0"/>
	</joint>
	<link name="torso_lift_link">
		<inertial>
			<origin rpy="0.00000 0.00000 0.00000" xyz="0.04361 -0.00116 -0.17334"/>
			<mass value="6.93198"/>
			<inertia ixx="0.24487000000" ixy="-0.00145600000" ixz="-0.00974200000" iyy="0.24926900000" iyz="0.00828100000" izz="0.09039500000"/>
		</inertial>
		<!-- Lifting body -->
		<visual>
			<origin rpy="0 0 0" xyz="0 0 0"/>
			<geometry>
				<mesh filename="package://tiago_description/meshes/torso/torso_lift_with_arm.stl" scale="1 1 1"/>
			</geometry>
			<material name="White"/>
		</visual>
		<collision>
			<origin rpy="0 0 0" xyz="0 0 0"/>
			<geometry>
				<mesh filename="package://tiago_description/meshes/torso/torso_lift_collision_core.dae" scale="1 1 1"/>
			</geometry>
			<material name="LightGrey"/>
		</collision>
		<collision>
			<origin rpy="0 0 0" xyz="0 0 0"/>
			<geometry>
				<mesh filename="package://tiago_description/meshes/torso/torso_lift_collision_shoulder.dae" scale="1 1 1"/>
			</geometry>
			<material name="LightGrey"/>
		</collision>
		<collision>
			<origin rpy="0 0 0" xyz="0 0 0"/>
			<geometry>
				<mesh filename="package://tiago_description/meshes/torso/torso_lift_collision_neck.dae" scale="1 1 1"/>
			</geometry>
			<material name="LightGrey"/>
		</collision>
	</link>
	<joint name="torso_lift_joint" type="prismatic">
		<origin rpy="0.0 0.0 0.0" xyz="0.0 0.0 0.597"/>
		<parent link="torso_fixed_link"/>
		<child link="torso_lift_link"/>
		<axis xyz="0 0 1"/>
		<limit effort="2000" lower="0" upper="0.35" velocity="0.07"/>
		<calibration rising="0.0"/>
		<dynamics damping="1000"/>
		<safety_controller k_position="20" k_velocity="20" soft_lower_limit="0.0" soft_upper_limit="0.35"/>
	</joint>
	<link name="head_1_link">
		<inertial>
			<origin rpy="0.00000 0.00000 0.00000" xyz="-0.00508 0.00237 0.07229"/>
			<mass value="0.62220"/>
			<inertia ixx="0.00119200000" ixy="-0.00000700000" ixz="0.00009600000" iyy="0.00140200000" iyz="0.00000400000" izz="0.00088900000"/>
		</inertial>
		<visual>
			<origin rpy="0 0 0" xyz="0 0 0"/>
			<geometry>
				<mesh filename="package://tiago_description/meshes/head/head_1.stl" scale="1 1 1"/>
			</geometry>
			<material name="White"/>
		</visual>
		<collision>
			<origin rpy="0 0 0.0" xyz="0.0 0 0"/>
			<geometry>
				<mesh filename="package://tiago_description/meshes/head/head_1_collision.dae" scale="1 1 1"/>
			</geometry>
			<material name="White"/>
		</collision>
	</link>
	<joint name="head_1_joint" type="revolute">
		<parent link="torso_lift_link"/>
		<child link="head_1_link"/>
		<origin rpy="0 0 0" xyz="0.182 0.0 0.0"/>
		<axis xyz="0 0 1"/>
		<limit effort="5.197" lower="-1.3089969389957472" upper="1.3089969389957472" velocity="3.0"/>
		<dynamics damping="0.5" friction="1.0"/>
		<safety_controller k_position="20" k_velocity="20" soft_lower_limit="-1.2389969389957471" soft_upper_limit="1.2389969389957471"/>
	</joint>
	<gazebo reference="head_1_link">
		<mu1>0.9</mu1>
		<mu2>0.9</mu2>
	</gazebo>
	<gazebo reference="head_1_joint">
		<implicitSpringDamper>1</implicitSpringDamper>
	</gazebo>
	<link name="head_2_link">
		<inertial>
			<origin rpy="0.00000 0.00000 0.00000" xyz="0.04700 0.05542 0.00022"/>
			<mass value="0.66123"/>
			<inertia ixx="0.00462000000" ixy="0.00068900000" ixz="0.00000600000" iyy="0.00486100000" iyz="0.00000600000" izz="0.00313200000"/>
		</inertial>
		<visual>
			<origin rpy="0 0 0" xyz="0 0 0"/>
			<geometry>
				<mesh filename="package://tiago_description/meshes/head/head_2.stl" scale="1 1 1"/>
			</geometry>
			<material name="White"/>
		</visual>
		<collision>
			<origin rpy="0 0 0" xyz="0 0 0"/>
			<geometry>
				<mesh filename="package://tiago_description/meshes/head/head_2_collision.dae" scale="1 1 1"/>
			</geometry>
		</collision>
	</link>
	<joint name="head_2_joint" type="revolute">
		<parent link="head_1_link"/>
		<child link="head_2_link"/>
		<origin rpy="1.5707963267948966 0 0" xyz="0.005 0.0 0.098"/>
		<axis xyz="0 0 1"/>
		<limit effort="2.77" lower="-1.0471975511965976" upper="0.7853981633974483" velocity="3.0"/>
		<dynamics damping="0.5" friction="1.0"/>
		<safety_controller k_position="20" k_velocity="20" soft_lower_limit="-0.9771975511965976" soft_upper_limit="0.7153981633974482"/>
	</joint>
	<!-- frames in the center of the camera -->
	<joint name="head_front_camera_joint" type="fixed">
		<origin rpy="-1.5707963267948966 0.0 0.0" xyz="0.0908 0.08 0.0"/>
		<parent link="head_2_link"/>
		<child link="head_front_camera_link"/>
	</joint>
	<link name="head_front_camera_link">
		<inertial>
			<origin rpy="0 0 0" xyz="-0.00936000000 -0.00003000000 -0.00273000000"/>
			<mass value="0.21970000000"/>
			<inertia ixx="0.00000429247" ixy="0.00000000000" ixz="0.00000002565" iyy="0.00000008027" iyz="0.00000000000" izz="0.00000427339"/>
		</inertial>
		<!--\n      <visual>\n        <origin xyz="0 0 0" rpy="0 0 0"/>\n        <geometry>\n          <mesh filename="package://tiago_description/meshes/sensors/xtion_pro_live/xtion_pro_live.dae" />\n        </geometry>\n        <material name="Grey">\n          <color rgba="0.5 0.5 0.5 1"/>\n        </material>\n      </visual>\n      <collision>\n        <origin xyz="-0.01 0.0025 0" rpy="0 0 0"/>\n        <geometry>\n          <box size="0.04 0.185 0.03"/>\n        </geometry>\n      </collision>\n      -->
	</link>
	<joint name="head_front_camera_optical_joint" type="fixed">
		<origin rpy="-1.5707963267948966 0.0 -1.5707963267948966" xyz="0 0 0"/>
		<parent link="head_front_camera_link"/>
		<child link="head_front_camera_optical_frame"/>
	</joint>
	<link name="head_front_camera_optical_frame">
		<inertial>
			<origin rpy="0 0 0" xyz="0 0 0"/>
			<mass value="0.001"/>
			<inertia ixx="0.00001" ixy="0" ixz="0" iyy="0.00001" iyz="0" izz="0.00001"/>
		</inertial>
	</link>
	<!-- frame of camera origin provided by Orbbec, need this intermediate frame for backwards compatibility with xtion_pro_live\n         to reuse same camera origin -->
	<joint name="head_front_camera_orbbec_aux_joint" type="fixed">
		<!-- Assuming we have 0.0908 0.08 0.0 from default camera_position, and rotated -90 deg on x.-->
		<!-- Pending confirmation from Orbbec about the position of the frames, going with old defaults-->
		<!-- <origin xyz="0.0107 0.008 0.015" rpy="0 0 0" />-->
		<origin rpy="0 0 0" xyz="0 0 0"/>
		<parent link="head_front_camera_link"/>
		<child link="head_front_camera_orbbec_aux_joint_frame"/>
	</joint>
	<link name="head_front_camera_orbbec_aux_joint_frame">
		<inertial>
			<origin rpy="0 0 0" xyz="0 0 0"/>
			<mass value="0.001"/>
			<inertia ixx="0.00001" ixy="0" ixz="0" iyy="0.00001" iyz="0" izz="0.00001"/>
		</inertial>
	</link>
	<!-- frames of the depth sensor -->
	<joint name="head_front_camera_depth_joint" type="fixed">
		<origin rpy="0 0 0" xyz="0.0 0.025 0.0"/>
		<parent link="head_front_camera_rgb_frame"/>
		<child link="head_front_camera_depth_frame"/>
	</joint>
	<link name="head_front_camera_depth_frame">
		<inertial>
			<origin rpy="0 0 0" xyz="0 0 0"/>
			<mass value="0.001"/>
			<inertia ixx="0.00001" ixy="0" ixz="0" iyy="0.00001" iyz="0" izz="0.00001"/>
		</inertial>
	</link>
	<joint name="head_front_camera_depth_optical_joint" type="fixed">
		<origin rpy="-1.5707963267948966 0.0 -1.5707963267948966" xyz="0 0 0"/>
		<parent link="head_front_camera_depth_frame"/>
		<child link="head_front_camera_depth_optical_frame"/>
	</joint>
	<link name="head_front_camera_depth_optical_frame">
		<inertial>
			<origin rpy="0 0 0" xyz="0 0 0"/>
			<mass value="0.001"/>
			<inertia ixx="0.00001" ixy="0" ixz="0" iyy="0.00001" iyz="0" izz="0.00001"/>
		</inertial>
	</link>
	<!-- frames of the rgb sensor -->
	<joint name="head_front_camera_rgb_joint" type="fixed">
		<origin rpy="0 0 0" xyz="0.0 0.022 0.0"/>
		<parent link="head_front_camera_orbbec_aux_joint_frame"/>
		<child link="head_front_camera_rgb_frame"/>
	</joint>
	<link name="head_front_camera_rgb_frame">
		<inertial>
			<origin rpy="0 0 0" xyz="0 0 0"/>
			<mass value="0.001"/>
			<inertia ixx="0.00001" ixy="0" ixz="0" iyy="0.00001" iyz="0" izz="0.00001"/>
		</inertial>
	</link>
	<joint name="head_front_camera_rgb_optical_joint" type="fixed">
		<origin rpy="-1.5707963267948966 0.0 -1.5707963267948966" xyz="0 0 0"/>
		<parent link="head_front_camera_rgb_frame"/>
		<child link="head_front_camera_rgb_optical_frame"/>
	</joint>
	<link name="head_front_camera_rgb_optical_frame">
		<inertial>
			<origin rpy="0 0 0" xyz="0 0 0"/>
			<mass value="0.001"/>
			<inertia ixx="0.00001" ixy="0" ixz="0" iyy="0.00001" iyz="0" izz="0.00001"/>
		</inertial>
	</link>
	<gazebo reference="head_front_camera_rgb_frame">
		<sensor name="head_front_camera_frame_sensor" type="depth">
			<always_on>true</always_on>
			<update_rate>30.0</update_rate>
			<camera>
				<horizontal_fov>1.0995574287564276</horizontal_fov>
				<image>
					<format>B8G8R8</format>
					<width>640</width>
					<height>480</height>
				</image>
				<clip>
					<near>0.3</near>
					<far>8.0</far>
				</clip>
				<distortion>
					<k1>0.00000001</k1>
					<k2>0.00000001</k2>
					<k3>0.00000001</k3>
					<p1>0.00000001</p1>
					<p2>0.00000001</p2>
				</distortion>
			</camera>
			<plugin filename="libgazebo_ros_camera.so" name="head_front_camera_frame_controller">
				<camera_name>head_front_camera</camera_name>
				<ros>
					<!-- <namespace>${name}</namespace>-->
					<remapping>head_front_camera/image_raw:=head_front_camera/rgb/image_raw</remapping>
					<remapping>head_front_camera/camera_info:=head_front_camera/rgb/camera_info</remapping>
					<remapping>head_front_camera/depth/image_raw:=head_front_camera/depth_registered/image_raw</remapping>
					<remapping>head_front_camera/depth/camera_info:=head_front_camera/depth_registered/camera_info</remapping>
					<remapping>head_front_camera/points:=head_front_camera/depth_registered/points</remapping>
				</ros>
				<frame_name>head_front_camera_rgb_optical_frame</frame_name>
				<min_depth>0.3</min_depth>
				<max_depth>8.0</max_depth>
			</plugin>
		</sensor>
	</gazebo>
	<!--************************-->
	<!--        SHOULDER        -->
	<!--************************-->
	<link name="arm_1_link">
		<inertial>
			<!--<origin xyz="0.061191 ${reflect * -0.022397} -0.012835" rpy="0.00000 0.00000 0.00000"/>-->
			<origin rpy="0.00000 0.00000 0.00000" xyz="0.061191 -0.022397 -0.012835"/>
			<mass value="1.563428"/>
			<inertia ixx="0.002471" ixy="-0.001809" ixz="-0.001202" iyy="0.006132" iyz="0.000494" izz="0.006704"/>
		</inertial>
		<!-- M90 module -->
		<visual>
			<origin rpy="0 0 0" xyz="0 0 0"/>
			<geometry>
				<mesh filename="package://tiago_description/meshes/arm/arm_1.stl" scale="1 1 1"/>
			</geometry>
			<material name="White"/>
		</visual>
		<collision>
			<origin rpy="0 0 0" xyz="0 0 0"/>
			<geometry>
				<mesh filename="package://tiago_description/meshes/arm/arm_1_collision.dae" scale="1 1 1"/>
			</geometry>
		</collision>
	</link>
	<joint name="arm_1_joint" type="revolute">
		<parent link="torso_lift_link"/>
		<child link="arm_1_link"/>
		<origin rpy="0 0 -1.5707963267948966" xyz="0.15505 0.014 -0.151"/>
		<axis xyz="0 0 1"/>
		<limit effort="43.0" lower="0.0" upper="2.748893571891069" velocity="1.95"/>
		<dynamics damping="40.0" friction="1.0"/>
		<safety_controller k_position="20" k_velocity="20" soft_lower_limit="0.07" soft_upper_limit="2.678893571891069"/>
	</joint>
	<link name="arm_2_link">
		<inertial>
			<origin rpy="0.00000 0.00000 0.00000" xyz="0.030432 0.000229 -0.005942"/>
			<mass value="1.800397"/>
			<inertia ixx="0.001809" ixy="1.5e-05" ixz="0.000254" iyy="0.004333" iyz="1.4e-05" izz="0.004341"/>
		</inertial>
		<visual>
			<!-- <origin xyz="0 0 0" rpy="${180 * deg_to_rad} ${0 * deg_to_rad} ${-90 * deg_to_rad}" />-->
			<origin rpy="0.0 0.0 0.0" xyz="0 0 0"/>
			<geometry>
				<mesh filename="package://tiago_description/meshes/arm/arm_2.stl" scale="1 1 1"/>
			</geometry>
			<material name="DarkGrey"/>
		</visual>
		<collision>
			<!-- <origin xyz="0 0 0" rpy="${180 * deg_to_rad} ${0 * deg_to_rad} ${-90 * deg_to_rad}" />-->
			<origin rpy="0.0 0.0 0.0" xyz="0 0 0"/>
			<geometry>
				<mesh filename="package://tiago_description/meshes/arm/arm_2_collision.dae" scale="1 1 1"/>
			</geometry>
		</collision>
	</link>
	<joint name="arm_2_joint" type="revolute">
		<parent link="arm_1_link"/>
		<child link="arm_2_link"/>
		<origin rpy="1.5707963267948966 0.0 0.0" xyz="0.125 0.0195 -0.031"/>
		<axis xyz="0 0 1"/>
		<limit effort="43.0" lower="-1.5707963267948966" upper="1.090830782496456" velocity="1.95"/>
		<dynamics damping="40.0" friction="1.0"/>
		<safety_controller k_position="20" k_velocity="20" soft_lower_limit="-1.5007963267948965" soft_upper_limit="1.020830782496456"/>
	</joint>
	<link name="arm_3_link">
		<inertial>
			<origin rpy="0.00000 0.00000 0.00000" xyz="0.007418 -0.004361 -0.134194"/>
			<mass value="1.8"/>
			<inertia ixx="0.019541" ixy="-0.000105" ixz="-0.001717" iyy="0.019936" iyz="0.000852" izz="0.002864"/>
		</inertial>
		<visual>
			<origin rpy="0 0 0" xyz="0 0 0"/>
			<geometry>
				<mesh filename="package://tiago_description/meshes/arm/arm_3.stl" scale="1 1 1"/>
			</geometry>
			<material name="DarkGrey"/>
		</visual>
		<collision>
			<origin rpy="0 0 0" xyz="0 0 0"/>
			<geometry>
				<mesh filename="package://tiago_description/meshes/arm/arm_3_collision.dae" scale="1 1 1"/>
			</geometry>
		</collision>
	</link>
	<joint name="arm_3_joint" type="revolute">
		<parent link="arm_2_link"/>
		<child link="arm_3_link"/>
		<origin rpy="-1.5707963267948966 0.0 1.5707963267948966" xyz="0.0895 0.0 -0.0015"/>
		<axis xyz="0 0 1"/>
		<limit effort="26" lower="-3.5342917352885173" upper="1.5707963267948966" velocity="2.35"/>
		<dynamics damping="40.0" friction="1.0"/>
		<safety_controller k_position="20" k_velocity="20" soft_lower_limit="-3.4642917352885174" soft_upper_limit="1.5007963267948965"/>
	</joint>
	<!--************************-->
	<!--        ELBOW           -->
	<!--************************-->
	<link name="arm_4_link">
		<inertial>
			<origin rpy="0.00000 0.00000 0.00000" xyz="-0.095658 0.014666 0.018133"/>
			<mass value="1.432697"/>
			<inertia ixx="0.002040" ixy="0.000725" ixz="-0.00115" iyy="0.008424" iyz="-0.000204" izz="0.008686"/>
		</inertial>
		<visual>
			<origin rpy="0 0 0" xyz="0 0 0"/>
			<geometry>
				<mesh filename="package://tiago_description/meshes/arm/arm_4.stl" scale="1 1 1"/>
			</geometry>
			<material name="DarkGrey"/>
		</visual>
		<collision>
			<origin rpy="0 0 0" xyz="0 0 0"/>
			<geometry>
				<mesh filename="package://tiago_description/meshes/arm/arm_4_collision.dae" scale="1 1 1"/>
			</geometry>
		</collision>
	</link>
	<joint name="arm_4_joint" type="revolute">
		<parent link="arm_3_link"/>
		<child link="arm_4_link"/>
		<origin rpy="-1.5707963267948966 -1.5707963267948966 0.0" xyz="-0.02 -0.027 -0.222"/>
		<axis xyz="0 0 1"/>
		<limit effort="26" lower="-0.39269908169872414" upper="2.356194490192345" velocity="2.35"/>
		<dynamics damping="40.0" friction="1.0"/>
		<safety_controller k_position="20" k_velocity="20" soft_lower_limit="-0.32269908169872413" soft_upper_limit="2.286194490192345"/>
	</joint>
	<gazebo reference="arm_1_link">
		<mu1>0.9</mu1>
		<mu2>0.9</mu2>
		<material>Gazebo/DarkGrey</material>
	</gazebo>
	<gazebo reference="arm_2_link">
		<mu1>0.9</mu1>
		<mu2>0.9</mu2>
		<material>Gazebo/DarkGrey</material>
	</gazebo>
	<gazebo reference="arm_3_link">
		<mu1>0.9</mu1>
		<mu2>0.9</mu2>
		<material>Gazebo/DarkGrey</material>
	</gazebo>
	<gazebo reference="arm_4_link">
		<mu1>0.9</mu1>
		<mu2>0.9</mu2>
		<material>Gazebo/DarkGrey</material>
	</gazebo>
	<gazebo reference="arm_1_joint">
		<implicitSpringDamper>1</implicitSpringDamper>
	</gazebo>
	<gazebo reference="arm_2_joint">
		<implicitSpringDamper>1</implicitSpringDamper>
	</gazebo>
	<gazebo reference="arm_3_joint">
		<implicitSpringDamper>1</implicitSpringDamper>
	</gazebo>
	<gazebo reference="arm_4_joint">
		<implicitSpringDamper>1</implicitSpringDamper>
	</gazebo>
	<!--************************-->
	<!--        WRIST           -->
	<!--************************-->
	<!--************************-->
	<!--        WRIST           -->
	<!--************************-->
	<link name="arm_5_link">
		<inertial>
			<origin rpy="0.00000 0.00000 0.00000" xyz="0.001078 -0.000151 -0.077173"/>
			<mass value="1.655819"/>
			<inertia ixx="0.00613800000" ixy="-0.00000400000" ixz="0.00015600000" iyy="0.00564000000" iyz="0.00002200000" izz="0.00179700000"/>
		</inertial>
		<visual>
			<origin rpy="0 0 0" xyz="0 0 0"/>
			<geometry>
				<mesh filename="package://tiago_description/meshes/arm/arm_5-wrist-2010.stl" scale="1 1 1"/>
			</geometry>
			<material name="LightGrey"/>
		</visual>
		<collision>
			<origin rpy="0 0 0" xyz="0 0 0"/>
			<geometry>
				<mesh filename="package://tiago_description/meshes/arm/arm_5_collision-wrist-2010.dae" scale="1 1 1"/>
			</geometry>
		</collision>
	</link>
	<joint name="arm_5_joint" type="revolute">
		<parent link="arm_4_link"/>
		<child link="arm_5_link"/>
		<origin rpy="1.5707963267948966 -1.5707963267948966 -1.5707963267948966" xyz="-0.162 0.02 0.027"/>
		<axis xyz="0 0 1"/>
		<limit effort="3" lower="-2.0943951023931953" upper="2.0943951023931953" velocity="1.95"/>
		<dynamics damping="1.0" friction="1.0"/>
		<safety_controller k_position="20" k_velocity="20" soft_lower_limit="-2.0743951023931952" soft_upper_limit="2.0743951023931952"/>
	</joint>
	<link name="arm_6_link">
		<inertial>
			<origin rpy="0.00000 0.00000 0.00000" xyz="-0.000153 -0.003122 0.000183"/>
			<mass value="0.370063"/>
			<inertia ixx="0.00021500000" ixy="0.00000000000" ixz="0.00000000000" iyy="0.00017000000" iyz="0.00000200000" izz="0.00017400000"/>
		</inertial>
		<visual>
			<origin rpy="0 0 0" xyz="0 0 0"/>
			<geometry>
				<mesh filename="package://tiago_description/meshes/arm/arm_6-wrist-2010.stl" scale="1 1 1"/>
			</geometry>
			<material name="LightGrey"/>
		</visual>
		<collision>
			<origin rpy="0 0 0" xyz="0 0 0"/>
			<geometry>
				<mesh filename="package://tiago_description/meshes/arm/arm_6_collision-wrist-2010.dae" scale="1 1 1"/>
			</geometry>
		</collision>
	</link>
	<joint name="arm_6_joint" type="revolute">
		<parent link="arm_5_link"/>
		<child link="arm_6_link"/>
		<origin rpy="0.0 -1.5707963267948966 -1.5707963267948966" xyz="0 0 0.15"/>
		<axis xyz="0 0 1"/>
		<limit effort="6.6" lower="-1.413716694115407" upper="1.413716694115407" velocity="1.76"/>
		<dynamics damping="1.0" friction="1.0"/>
		<safety_controller k_position="20" k_velocity="20" soft_lower_limit="-1.3937166941154069" soft_upper_limit="1.3937166941154069"/>
	</joint>
	<link name="arm_7_link">
		<inertial>
			<origin rpy="0.00000 0.00000 0.00000" xyz="0.000010 -0.000003 -0.007774"/>
			<mass value="0.234252"/>
			<inertia ixx="0.00014200000" ixy="0.00000000000" ixz="0.00000000000" iyy="0.00011300000" iyz="0.00000000000" izz="0.00005200000"/>
		</inertial>
	</link>
	<joint name="arm_7_joint" type="revolute">
		<parent link="arm_6_link"/>
		<child link="arm_7_link"/>
		<origin rpy="1.5707963267948966 0.0 1.5707963267948966" xyz="0 0 0"/>
		<axis xyz="0 0 1"/>
		<limit effort="6.6" lower="-2.0943951023931953" upper="2.0943951023931953" velocity="1.76"/>
		<dynamics damping="1.0" friction="1.0"/>
		<safety_controller k_position="20" k_velocity="20" soft_lower_limit="-2.0743951023931952" soft_upper_limit="2.0743951023931952"/>
	</joint>
	<gazebo reference="arm_5_link">
		<mu1>0.9</mu1>
		<mu2>0.9</mu2>
	</gazebo>
	<gazebo reference="arm_6_link">
		<mu1>0.9</mu1>
		<mu2>0.9</mu2>
	</gazebo>
	<gazebo reference="arm_7_link">
		<mu1>0.9</mu1>
		<mu2>0.9</mu2>
	</gazebo>
	<gazebo reference="arm_5_joint">
		<implicitSpringDamper>1</implicitSpringDamper>
	</gazebo>
	<gazebo reference="arm_6_joint">
		<implicitSpringDamper>1</implicitSpringDamper>
	</gazebo>
	<gazebo reference="arm_7_joint">
		<implicitSpringDamper>1</implicitSpringDamper>
		<provideFeedback>1</provideFeedback>
	</gazebo>
	<!--***********************-->
	<!--        TOOL           -->
	<!--***********************-->
	<link name="arm_tool_link">
		<inertial>
			<mass value="0.1"/>
			<inertia ixx="0.0" ixy="0.0" ixz="0.0" iyy="0.0" iyz="0.0" izz="0.0"/>
		</inertial>
		<visual>
			<origin rpy="0 1.5707963267948966 0" xyz="0.001 0 0"/>
			<geometry>
				<cylinder length="0.005" radius="0.005"/>
			</geometry>
			<material name="LightGrey"/>
		</visual>
		<collision>
			<origin rpy="0 1.5707963267948966 0" xyz="0.001 0 0"/>
			<geometry>
				<cylinder length="0.005" radius="0.005"/>
			</geometry>
		</collision>
	</link>
	<joint name="arm_tool_joint" type="fixed">
		<parent link="arm_7_link"/>
		<child link="arm_tool_link"/>
		<origin rpy="1.5707963267948966 -1.5707963267948966 3.141592653589793" xyz="0 0 0.046"/>
	</joint>
	<link name="gripper_tool_link">
		<inertial>
			<origin rpy="0 0 0" xyz="0 0 0"/>
			<mass value="0.0001"/>
			<inertia ixx="0.00001" ixy="0.0" ixz="0.0" iyy="0.00001" iyz="0.0" izz="0.00001"/>
		</inertial>
	</link>
	<joint name="gripper_tool_joint" type="fixed">
		<origin rpy="1.5707963267948966 1.5707963267948966 -1.5707963267948966" xyz="0.01 0 0"/>
		<parent link="wrist_ft_tool_link"/>
		<child link="gripper_tool_link"/>
		<axis xyz="0 0 0"/>
	</joint>
	<link name="gripper_link">
		<inertial>
			<origin rpy="0.0 0.0 0.0" xyz="-0.000294 0.000291 -0.033086"/>
			<mass value="0.602660"/>
			<inertia ixx="0.000693" ixy="0.000045" ixz="-0.000000" iyy="0.001024" iyz="0.000000" izz="0.000672"/>
		</inertial>
		<visual>
			<origin rpy="0 0 0" xyz="0 0 0"/>
			<geometry>
				<mesh filename="package://pal_gripper_description/meshes/gripper_link.stl"/>
			</geometry>
			<material name="White"/>
		</visual>
		<collision>
			<origin rpy="0 0 0" xyz="0 0 0"/>
			<geometry>
				<mesh filename="package://pal_gripper_description/meshes/gripper_link_collision.stl"/>
			</geometry>
		</collision>
	</link>
	<gazebo reference="gripper_link">
		<material>Gazebo/White</material>
	</gazebo>
	<joint name="gripper_joint" type="fixed">
		<origin rpy="1.5707963267948966 1.5707963267948966 -1.5707963267948966" xyz="0.01 0 0"/>
		<parent link="wrist_ft_tool_link"/>
		<child link="gripper_link"/>
		<axis xyz="0 0 0"/>
	</joint>
	<link name="gripper_right_finger_link">
		<inertial>
			<origin rpy="0 0 0" xyz="-0.004470 0.010766 -0.121013"/>
			<mass value="0.109980"/>
			<inertia ixx="0.000232" ixy="-0.000005" ixz="-0.000032" iyy="0.000224" iyz="0.000036" izz="0.000029"/>
		</inertial>
		<visual>
			<origin rpy="0 0 3.1415" xyz="0 0 0"/>
			<geometry>
				<mesh filename="package://pal_gripper_description/meshes/gripper_finger_link.stl" scale="-1 -1 1"/>
			</geometry>
			<material name="Black"/>
		</visual>
		<collision>
			<origin rpy="0 0 3.1415" xyz="0.005 0 -0.165"/>
			<geometry>
				<box size="0.01 0.05 0.11"/>
			</geometry>
		</collision>
	</link>
	<gazebo reference="gripper_right_finger_link">
		<material>Gazebo/Black</material>
	</gazebo>
	<joint name="gripper_right_finger_joint" type="prismatic">
		<origin rpy="0 0 0" xyz="0. 0 0"/>
		<parent link="gripper_link"/>
		<child link="gripper_right_finger_link"/>
		<axis xyz="1 0 0"/>
		<limit effort="16" lower="0.0" upper="0.045" velocity="0.05"/>
		<calibration rising="0.0"/>
		<dynamics damping="80" friction="2.0"/>
		<safety_controller k_position="20" k_velocity="20" soft_lower_limit="0.001" soft_upper_limit="0.044"/>
	</joint>
	<link name="gripper_left_finger_link">
		<inertial>
			<origin rpy="0 0 0" xyz="-0.004470 0.010766 -0.121013"/>
			<mass value="0.109980"/>
			<inertia ixx="0.000232" ixy="-0.000005" ixz="-0.000032" iyy="0.000224" iyz="0.000036" izz="0.000029"/>
		</inertial>
		<visual>
			<origin rpy="0 0 3.1415" xyz="0 0 0"/>
			<geometry>
				<mesh filename="package://pal_gripper_description/meshes/gripper_finger_link.stl"/>
			</geometry>
			<material name="Black"/>
		</visual>
		<collision>
			<origin rpy="0 0 3.1415" xyz="-0.005 0 -0.165"/>
			<geometry>
				<box size="0.01 0.05 0.11"/>
			</geometry>
		</collision>
	</link>
	<gazebo reference="gripper_left_finger_link">
		<material>Gazebo/Black</material>
	</gazebo>
	<joint name="gripper_left_finger_joint" type="prismatic">
		<origin rpy="0 0 0" xyz="0. 0 0"/>
		<parent link="gripper_link"/>
		<child link="gripper_left_finger_link"/>
		<axis xyz="-1 0 0"/>
		<limit effort="16" lower="0" upper="0.045" velocity="0.05"/>
		<calibration rising="0.0"/>
		<dynamics damping="80" friction="2.0"/>
		<safety_controller k_position="20" k_velocity="20" soft_lower_limit="0.001" soft_upper_limit="0.044"/>
	</joint>
	<!-- Grasping frame -->
	<joint name="gripper_grasping_frame_joint" type="fixed">
		<parent link="gripper_link"/>
		<child link="gripper_grasping_frame"/>
		<origin rpy="-1.5708 1.5708 0" xyz="0 0 -0.12"/>
	</joint>
	<link name="gripper_grasping_frame">
		<inertial>
			<origin rpy="0 0 0" xyz="0 0 0"/>
			<mass value="0.0001"/>
			<inertia ixx="0.00001" ixy="0.0" ixz="0.0" iyy="0.00001" iyz="0.0" izz="0.00001"/>
		</inertial>
	</link>
	<gazebo reference="gripper_left_finger_link">
		<kp>1000000.0</kp>
		<kd>1.0</kd>
		<mu1>1.0</mu1>
		<mu2>1.0</mu2>
		<fdir1>0 0 0</fdir1>
		<maxVel>1.0</maxVel>
		<minDepth>0.1</minDepth>
		<material>Gazebo/Black</material>
	</gazebo>
	<gazebo reference="gripper_left_finger_joint">
		<implicitSpringDamper>1</implicitSpringDamper>
		<provideFeedback>1</provideFeedback>
	</gazebo>
	<gazebo reference="gripper_right_finger_link">
		<kp>1000000.0</kp>
		<kd>1.0</kd>
		<mu1>1.0</mu1>
		<mu2>1.0</mu2>
		<fdir1>0 0 0</fdir1>
		<maxVel>1.0</maxVel>
		<minDepth>0.1</minDepth>
		<material>Gazebo/Black</material>
	</gazebo>
	<gazebo reference="gripper_right_finger_joint">
		<implicitSpringDamper>1</implicitSpringDamper>
		<provideFeedback>1</provideFeedback>
	</gazebo>
	<!-- Schunk WSG -->
	<!-- <xacro:if value="${type == 'schunk-wsg'}">\n    <xacro:include filename="$(find pal_wsg_gripper_description)/urdf/gripper.urdf.xacro" />\n    <xacro:include filename="$(find pal_wsg_gripper_description)/urdf/fingertip_sensor.urdf.xacro" />\n\n    <xacro:pal_wsg_gripper parent="${parent}" name="${name}">\n      <origin xyz="0.01 0 0" rpy="${90*deg_to_rad} ${90*deg_to_rad} ${-90*deg_to_rad}"/>\n    </xacro:pal_wsg_gripper>-->
	<!-- Fingertip sensors -->
	<!-- <xacro:fingertip_sensor name="${name}_left" parent="${name}_left_finger">\n      <origin xyz="0.035 0 -0.1465" rpy="0 ${-90*deg_to_rad} 0"/>\n    </xacro:fingertip_sensor>\n    <xacro:fingertip_sensor name="${name}_right" parent="${name}_right_finger">\n      <origin xyz="-0.035 0 -0.1465" rpy="0 ${90*deg_to_rad} 0"/>\n    </xacro:fingertip_sensor>\n  </xacro:if>-->
	<!-- Custom -->
	<!-- <xacro:if value="${type == 'custom'}">\n    <xacro:include filename="$(find custom_ee_description)/urdf/end-effector.urdf.xacro" />\n    <xacro:end_effector parent="${parent}">\n      <origin xyz="0.01 0 0" rpy="${90*deg_to_rad} ${90*deg_to_rad} ${-90*deg_to_rad}"/>\n    </xacro:end_effector>\n  </xacro:if>-->
	<!--************************-->
	<!--        ft sensor       -->
	<!--************************-->
	<link name="wrist_ft_link">
		<inertial>
			<mass value="0.1"/>
			<inertia ixx="0.0" ixy="0.0" ixz="0.0" iyy="0.0" iyz="0.0" izz="0.0"/>
		</inertial>
		<visual>
			<origin rpy="0 0 0" xyz="0 0 0"/>
			<geometry>
				<cylinder length="0.0157" radius="0.0225"/>
			</geometry>
			<material name="LightGrey"/>
		</visual>
		<collision>
			<origin rpy="0 0 0" xyz="0 0 0"/>
			<geometry>
				<cylinder length="0.0157" radius="0.0225"/>
			</geometry>
		</collision>
	</link>
	<joint name="wrist_ft_joint" type="fixed">
		<parent link="arm_tool_link"/>
		<child link="wrist_ft_link"/>
		<origin rpy="1.5707963267948966 0 1.5707963267948966" xyz="0.00785 0 0"/>
	</joint>
	<!--***********************-->
	<!--       FT TOOL         -->
	<!--***********************-->
	<link name="wrist_ft_tool_link">
		<inertial>
			<mass value="0.1"/>
			<inertia ixx="0.0" ixy="0.0" ixz="0.0" iyy="0.0" iyz="0.0" izz="0.0"/>
		</inertial>
		<visual>
			<origin rpy="0 1.5707963267948966 0" xyz="0.0 0 0"/>
			<geometry>
				<cylinder length="0.00975" radius="0.025"/>
			</geometry>
			<material name="FlatBlack"/>
		</visual>
		<collision>
			<origin rpy="0 1.5707963267948966 0" xyz="0.0 0 0"/>
			<geometry>
				<cylinder length="0.00975" radius="0.025"/>
			</geometry>
		</collision>
	</link>
	<joint name="wrist_tool_joint" type="fixed">
		<parent link="wrist_ft_link"/>
		<child link="wrist_ft_tool_link"/>
		<origin rpy="-1.5707963267948966 -1.5707963267948966 0" xyz="0 0 0.012725"/>
	</joint>
	<!-- RGBD Laser Link -->
	<joint name="rgbd_laser_joint" type="fixed">
		<parent link="base_footprint"/>
		<child link="rgbd_laser_link"/>
		<origin rpy="0 0 0" xyz="-0.9 0 0"/>
	</joint>
	<link name="rgbd_laser_link">
		<inertial>
			<origin rpy="0 0 0" xyz="0 0 0"/>
			<mass value="0.0001"/>
			<inertia ixx="0.0001" ixy="0" ixz="0" iyy="0.0001" iyz="0" izz="0.0001"/>
		</inertial>
	</link>
	<gazebo reference="wrist_ft_joint">
		<preserveFixedJoint>true</preserveFixedJoint>
		<!-- in case this is in a fixed joint -->
		<sensor name="wrist_ft_joint_force_torque" type="force_torque">
			<update_rate>100</update_rate>
			<visualize>true</visualize>
			<force_torque>
				<frame>child</frame>
				<measure_direction>child_to_parent</measure_direction>
			</force_torque>
		</sensor>
	</gazebo>
</robot>
